<?xml version="1.0" ?>
<robot name="my_robot" xmlns:xacro="http://ros.org/wiki/xacro">
  <xacro:include filename="$(find my_project)/urdf/common_properties.xacro"/>
  <xacro:include filename="$(find my_project)/urdf/robot.gazebo.xacro"/>

  <link name="base_footprint"/>

  <joint name="base_joint" type="fixed">
    <pose>0 0 0 0 0 0</pose>
    <parent link="base_footprint"/>
    <child link="base_link"/>
  </joint>

  <link name="base_link">
    <pose>0 0 0 0 0 0</pose>
    <visual>
      <origin xyz="0.06 0.006 -0.3" rpy="0 0 -1.5708" />
      <geometry>
        <mesh filename="package://my_project/meshes/bases/Base.stl" scale="0.001 0.001 0.001"/>
      </geometry>
      <material name="light_black"/>
    </visual>

    <collision>
      <geometry>
        <cylinder length="0.6" radius="0.15"/>
      </geometry>
    </collision>

    <inertial>
      <mass value="5"/>
      <inertia ixx="0.17812" ixy="0" ixz="0"
               iyy="0.17812" iyz="0"
               izz="0.05624" />
    </inertial>
  </link>

  <joint name="wheel_left_joint" type="continuous">
    <parent link="base_link"/>
    <child link="wheel_left_link"/>
    <origin xyz="0.027 0.17 -0.3" rpy="-1.57 0 0"/>
    <axis xyz="0 0 1"/>
  </joint>

  <link name="wheel_left_link">
    <visual>
      <origin xyz="0 0 0" rpy="1.57 0 0"/>
      <geometry>
        <mesh filename="package://my_project/meshes/wheels/left_tire.stl" scale="0.001 0.001 0.001"/>
      </geometry>
      <material name="dark"/>
    </visual>

    <collision>
      <origin xyz="0 0 0" rpy="0 0 0"/>
      <geometry>
        <cylinder length="0.02" radius="0.0325"/>
      </geometry>
    </collision>

    <inertial>
      <origin xyz="0 0 0" />
      <mass value="0.3" />
      <inertia ixx="8.921875e-05" ixy="0" ixz="0"
               iyy="8.921875e-05" iyz="0"
               izz="0.000158" />
      </inertial>
  </link>

  <transmission name="wheel_left_tran">
    <type>transmission_interface/SimpleTransmission</type>
    <joint name="wheel_left_joint">
      <hardwareInterface>hardware_interface/VelocityJointInterface</hardwareInterface>
    </joint>
    <actuator name="wheel_left_motor">
      <hardwareInterface>VelocityJointInterface</hardwareInterface>
      <mechanicalReduction>1</mechanicalReduction>
    </actuator>
  </transmission>

  <joint name="wheel_right_joint" type="continuous">
    <parent link="base_link"/>
    <child link="wheel_right_link"/>
    <origin xyz="0.027 -0.17 -0.3" rpy="-1.57 0 0"/>
    <axis xyz="0 0 1"/>
  </joint>

  <link name="wheel_right_link">
    <visual>
      <origin xyz="0 0 0" rpy="1.57 0 0"/>
      <geometry>
        <mesh filename="package://my_project/meshes/wheels/right_tire.stl" scale="0.001 0.001 0.001"/>
      </geometry>
      <material name="dark"/>
    </visual>

    <collision>
      <origin xyz="0 0 0" rpy="0 0 0"/>
      <geometry>
        <cylinder length="0.018" radius="0.033"/>
      </geometry>
    </collision>

    <inertial>
      <origin xyz="0 0 0" />
      <mass value="0.3" />
      <inertia ixx="8.921875e-05" ixy="0" ixz="0"
               iyy="8.921875e-05" iyz="0"
               izz="0.000158" />
      </inertial>
  </link>

  <transmission name="wheel_right_tran">
    <type>transmission_interface/SimpleTransmission</type>
    <joint name="wheel_right_joint">
      <hardwareInterface>hardware_interface/VelocityJointInterface</hardwareInterface>
    </joint>
    <actuator name="wheel_right_motor">
      <hardwareInterface>VelocityJointInterface</hardwareInterface>
      <mechanicalReduction>1</mechanicalReduction>
    </actuator>
  </transmission>

  <joint name="caster_back_joint" type="fixed">
    <parent link="base_link"/>
    <child link="caster_back_link"/>
    <origin xyz="-0.1 0 -0.31625" rpy="-1.57 0 0"/>
  </joint>

  <link name="caster_back_link">
    <collision>
      <origin xyz="0 0 0" rpy="0 0 0"/>
      <geometry>
        <box size="0.03 0.03 0.03"/>
      </geometry>
    </collision>

    <inertial>
      <origin xyz="0 0 0" />
      <mass value="0.005" />
      <inertia ixx="0.001" ixy="0.0" ixz="0.0"
               iyy="0.001" iyz="0.0"
               izz="0.001" />
    </inertial>
  </link>

  <joint name="caster_front_joint" type="fixed">
    <parent link="base_link"/>
    <child link="caster_front_link"/>
    <origin xyz="0.1 0 -0.31625" rpy="-1.57 0 0"/>
  </joint>

  <link name="caster_front_link">
    <collision>
      <origin xyz="0 0 0" rpy="0 0 0"/>
      <geometry>
        <box size="0.032 0.032 0.032"/>
      </geometry>
    </collision>

    <inertial>
      <origin xyz="0 0 0" />
      <mass value="0.005" />
      <inertia ixx="0.001" ixy="0.0" ixz="0.0"
               iyy="0.001" iyz="0.0"
               izz="0.001" />
    </inertial>
  </link>

  <joint name="camera_joint" type="fixed">
    <origin xyz="0.0 0.0 0.2" rpy="0 0.0 0"/>
    <parent link="base_link"/>
    <child link="camera_link"/>
  </joint>

  <link name="camera_link">
    <collision>
      <origin xyz="0.16 0.0 0.0" rpy="0 0 0"/>
      <geometry>
        <box size="0.005 0.015 0.015"/>
      </geometry>
    </collision>
  </link>

  <joint name="camera_rgb_joint" type="fixed">
    <origin xyz="0.16 0.0 0.0" rpy="0 0 0"/>
    <parent link="camera_link"/>
    <child link="camera_rgb_frame"/>
  </joint>
  <link name="camera_rgb_frame"/>

  <joint name="camera_rgb_optical_joint" type="fixed">
    <origin xyz="0.0 0 0" rpy="0 0 0"/>
    <parent link="camera_rgb_frame"/>
    <child link="camera_rgb_optical_frame"/>
  </joint>
  <link name="camera_rgb_optical_frame"/>

  <joint name="sonar1_joint" type="fixed">
    <parent link="base_link"/>
    <child link="sonar1_link" />
    <origin xyz="0.11780 0.11780 -0.25" rpy="0 0 0.7853"/>
  </joint>

  <link name="sonar1_link">
  </link>

  <joint name="sonar2_joint" type="fixed">
    <parent link="base_link"/>
    <child link="sonar2_link" />
    <origin xyz="0.11780 -0.11780 -0.25" rpy="0 0 -0.7853"/>
  </joint>

  <link name="sonar2_link">
  </link>

  <joint name="sonar3_joint" type="fixed">
    <parent link="base_link"/>
    <child link="sonar3_link" />
    <origin xyz="-0.11780 0.11780 -0.25" rpy="0 0 2.35619"/>
  </joint>

  <link name="sonar3_link">
  </link>

  <joint name="sonar4_joint" type="fixed">
    <parent link="base_link"/>
    <child link="sonar4_link" />
    <origin xyz="-0.11780 -0.11780 -0.25" rpy="0 0 -2.35619"/>
  </joint>

  <link name="sonar4_link">
  </link>

</robot>
